[2023-06-08 15:48:46,308][whylogs.api.writer.whylabs][INFO] - checking: https://whylabs-public.s3.us-west-2.amazonaws.com/whylogs_config/whylabs_condition_count_disabled
[2023-06-08 15:48:46,372][whylogs.api.writer.whylabs][WARNING] - Error trying to read whylabs config, falling back to defaults for uncompounding
[2023-06-08 15:48:46,735][urllib3.connectionpool][WARNING] - Retrying (Retry(total=2, connect=None, read=None, redirect=None, status=None)) after connection broken by 'NewConnectionError('<urllib3.connection.HTTPSConnection object at 0x000001885512B7F0>: Failed to establish a new connection: [Errno 11002] getaddrinfo failed')': /v0/organizations/org-YNx5UG/log/async/model-3
[2023-06-08 15:48:46,740][urllib3.connectionpool][WARNING] - Retrying (Retry(total=1, connect=None, read=None, redirect=None, status=None)) after connection broken by 'NewConnectionError('<urllib3.connection.HTTPSConnection object at 0x000001885512B970>: Failed to establish a new connection: [Errno 11002] getaddrinfo failed')': /v0/organizations/org-YNx5UG/log/async/model-3
[2023-06-08 15:48:46,745][urllib3.connectionpool][WARNING] - Retrying (Retry(total=0, connect=None, read=None, redirect=None, status=None)) after connection broken by 'NewConnectionError('<urllib3.connection.HTTPSConnection object at 0x000001885512BAF0>: Failed to establish a new connection: [Errno 11002] getaddrinfo failed')': /v0/organizations/org-YNx5UG/log/async/model-3
